[2025-07-07T10:07:28.102+0000] {taskinstance.py:1103} INFO - Dependencies all met for dep_context=non-requeueable deps ti=<TaskInstance: etl_fact_customer_service.run_etl_fact_customer_service manual__2025-07-07T10:07:25.196813+00:00 [queued]>
[2025-07-07T10:07:28.136+0000] {taskinstance.py:1103} INFO - Dependencies all met for dep_context=requeueable deps ti=<TaskInstance: etl_fact_customer_service.run_etl_fact_customer_service manual__2025-07-07T10:07:25.196813+00:00 [queued]>
[2025-07-07T10:07:28.137+0000] {taskinstance.py:1308} INFO - Starting attempt 1 of 2
[2025-07-07T10:07:28.160+0000] {taskinstance.py:1327} INFO - Executing <Task(PythonOperator): run_etl_fact_customer_service> on 2025-07-07 10:07:25.196813+00:00
[2025-07-07T10:07:28.192+0000] {standard_task_runner.py:57} INFO - Started process 849 to run task
[2025-07-07T10:07:28.201+0000] {standard_task_runner.py:84} INFO - Running: ['airflow', 'tasks', 'run', 'etl_fact_customer_service', 'run_etl_fact_customer_service', 'manual__2025-07-07T10:07:25.196813+00:00', '--job-id', '320', '--raw', '--subdir', 'DAGS_FOLDER/etl_fact_customer_service.py', '--cfg-path', '/tmp/tmpbss6ckwr']
[2025-07-07T10:07:28.206+0000] {standard_task_runner.py:85} INFO - Job 320: Subtask run_etl_fact_customer_service
[2025-07-07T10:07:28.362+0000] {task_command.py:410} INFO - Running <TaskInstance: etl_fact_customer_service.run_etl_fact_customer_service manual__2025-07-07T10:07:25.196813+00:00 [running]> on host 1622b3ff66d0
[2025-07-07T10:07:28.756+0000] {taskinstance.py:1547} INFO - Exporting env vars: AIRFLOW_CTX_DAG_OWNER='airflow' AIRFLOW_CTX_DAG_ID='etl_fact_customer_service' AIRFLOW_CTX_TASK_ID='run_etl_fact_customer_service' AIRFLOW_CTX_EXECUTION_DATE='2025-07-07T10:07:25.196813+00:00' AIRFLOW_CTX_TRY_NUMBER='1' AIRFLOW_CTX_DAG_RUN_ID='manual__2025-07-07T10:07:25.196813+00:00'
[2025-07-07T10:07:28.810+0000] {base.py:73} INFO - Using connection ID '***_insurance_bi' for task execution.
[2025-07-07T10:07:37.198+0000] {base.py:73} INFO - Using connection ID '***_insurance_dw' for task execution.
[2025-07-07T10:07:40.586+0000] {base.py:73} INFO - Using connection ID '***_insurance_dw' for task execution.
[2025-07-07T10:07:40.928+0000] {base.py:73} INFO - Using connection ID '***_insurance_dw' for task execution.
[2025-07-07T10:07:42.833+0000] {base.py:73} INFO - Using connection ID '***_insurance_dw' for task execution.
[2025-07-07T10:07:43.004+0000] {taskinstance.py:1824} ERROR - Task failed with exception
Traceback (most recent call last):
  File "/home/airflow/.local/lib/python3.7/site-packages/airflow/operators/python.py", line 181, in execute
    return_value = self.execute_callable()
  File "/home/airflow/.local/lib/python3.7/site-packages/airflow/operators/python.py", line 198, in execute_callable
    return self.python_callable(*self.op_args, **self.op_kwargs)
  File "/opt/airflow/dags/etl_fact_customer_service.py", line 184, in etl_fact_customer_service
    transformed_df = transform_customer_service(df)
  File "/opt/airflow/dags/etl_fact_customer_service.py", line 66, in transform_customer_service
    df = pd.merge(df, cust_keys, on='customer_id', how='left')
  File "/home/airflow/.local/lib/python3.7/site-packages/pandas/core/reshape/merge.py", line 119, in merge
    validate=validate,
  File "/home/airflow/.local/lib/python3.7/site-packages/pandas/core/reshape/merge.py", line 703, in __init__
    self._maybe_coerce_merge_keys()
  File "/home/airflow/.local/lib/python3.7/site-packages/pandas/core/reshape/merge.py", line 1256, in _maybe_coerce_merge_keys
    raise ValueError(msg)
ValueError: You are trying to merge on int64 and object columns. If you wish to proceed you should use pd.concat
[2025-07-07T10:07:43.066+0000] {taskinstance.py:1350} INFO - Marking task as UP_FOR_RETRY. dag_id=etl_fact_customer_service, task_id=run_etl_fact_customer_service, execution_date=20250707T100725, start_date=20250707T100728, end_date=20250707T100743
[2025-07-07T10:07:43.130+0000] {standard_task_runner.py:109} ERROR - Failed to execute job 320 for task run_etl_fact_customer_service (You are trying to merge on int64 and object columns. If you wish to proceed you should use pd.concat; 849)
[2025-07-07T10:07:43.203+0000] {local_task_job_runner.py:225} INFO - Task exited with return code 1
[2025-07-07T10:07:43.330+0000] {taskinstance.py:2653} INFO - 0 downstream tasks scheduled from follow-on schedule check
