[2025-07-07T02:05:02.930+0000] {taskinstance.py:1103} INFO - Dependencies all met for dep_context=non-requeueable deps ti=<TaskInstance: etl_fact_investment.run_etl_fact_investment scheduled__2025-07-06T02:00:00+00:00 [queued]>
[2025-07-07T02:05:02.938+0000] {taskinstance.py:1103} INFO - Dependencies all met for dep_context=requeueable deps ti=<TaskInstance: etl_fact_investment.run_etl_fact_investment scheduled__2025-07-06T02:00:00+00:00 [queued]>
[2025-07-07T02:05:02.939+0000] {taskinstance.py:1308} INFO - Starting attempt 2 of 2
[2025-07-07T02:05:02.949+0000] {taskinstance.py:1327} INFO - Executing <Task(PythonOperator): run_etl_fact_investment> on 2025-07-06 02:00:00+00:00
[2025-07-07T02:05:02.953+0000] {standard_task_runner.py:57} INFO - Started process 252 to run task
[2025-07-07T02:05:02.957+0000] {standard_task_runner.py:84} INFO - Running: ['airflow', 'tasks', 'run', 'etl_fact_investment', 'run_etl_fact_investment', 'scheduled__2025-07-06T02:00:00+00:00', '--job-id', '95', '--raw', '--subdir', 'DAGS_FOLDER/etl_fact_investment.py', '--cfg-path', '/tmp/tmpxzym3lq9']
[2025-07-07T02:05:02.958+0000] {standard_task_runner.py:85} INFO - Job 95: Subtask run_etl_fact_investment
[2025-07-07T02:05:03.151+0000] {task_command.py:410} INFO - Running <TaskInstance: etl_fact_investment.run_etl_fact_investment scheduled__2025-07-06T02:00:00+00:00 [running]> on host 1622b3ff66d0
[2025-07-07T02:05:03.769+0000] {taskinstance.py:1547} INFO - Exporting env vars: AIRFLOW_CTX_DAG_OWNER='airflow' AIRFLOW_CTX_DAG_ID='etl_fact_investment' AIRFLOW_CTX_TASK_ID='run_etl_fact_investment' AIRFLOW_CTX_EXECUTION_DATE='2025-07-06T02:00:00+00:00' AIRFLOW_CTX_TRY_NUMBER='2' AIRFLOW_CTX_DAG_RUN_ID='scheduled__2025-07-06T02:00:00+00:00'
[2025-07-07T02:05:03.909+0000] {base.py:73} INFO - Using connection ID '***_insurance_bi' for task execution.
[2025-07-07T02:05:04.069+0000] {taskinstance.py:1824} ERROR - Task failed with exception
Traceback (most recent call last):
  File "/home/airflow/.local/lib/python3.7/site-packages/pandas/io/sql.py", line 2056, in execute
    cur.execute(*args, **kwargs)
psycopg2.errors.UndefinedColumn: column i.tanggal_investasi does not exist
LINE 5:         i.tanggal_investasi, 
                ^


The above exception was the direct cause of the following exception:

Traceback (most recent call last):
  File "/home/airflow/.local/lib/python3.7/site-packages/airflow/operators/python.py", line 181, in execute
    return_value = self.execute_callable()
  File "/home/airflow/.local/lib/python3.7/site-packages/airflow/operators/python.py", line 198, in execute_callable
    return self.python_callable(*self.op_args, **self.op_kwargs)
  File "/opt/airflow/dags/etl_fact_investment.py", line 117, in etl_fact_investment
    df = extract_investment()
  File "/opt/airflow/dags/etl_fact_investment.py", line 30, in extract_investment
    df = source_hook.get_pandas_df(sql)
  File "/home/airflow/.local/lib/python3.7/site-packages/airflow/providers/common/sql/hooks/sql.py", line 201, in get_pandas_df
    return psql.read_sql(sql, con=conn, params=parameters, **kwargs)
  File "/home/airflow/.local/lib/python3.7/site-packages/pandas/io/sql.py", line 608, in read_sql
    chunksize=chunksize,
  File "/home/airflow/.local/lib/python3.7/site-packages/pandas/io/sql.py", line 2116, in read_query
    cursor = self.execute(*args)
  File "/home/airflow/.local/lib/python3.7/site-packages/pandas/io/sql.py", line 2068, in execute
    raise ex from exc
pandas.io.sql.DatabaseError: Execution failed on sql '
    SELECT 
        i.investment_id, 
        i.policy_id, 
        i.tanggal_investasi, 
        i.nilai_investasi, 
        i.jenis_investasi, 
        i.return, 
        i.tanggal_jatuh_tempo
    FROM investment i
    ': column i.tanggal_investasi does not exist
LINE 5:         i.tanggal_investasi, 
                ^

[2025-07-07T02:05:04.124+0000] {taskinstance.py:1350} INFO - Marking task as FAILED. dag_id=etl_fact_investment, task_id=run_etl_fact_investment, execution_date=20250706T020000, start_date=20250707T020502, end_date=20250707T020504
[2025-07-07T02:05:04.171+0000] {standard_task_runner.py:109} ERROR - Failed to execute job 95 for task run_etl_fact_investment (Execution failed on sql '
    SELECT 
        i.investment_id, 
        i.policy_id, 
        i.tanggal_investasi, 
        i.nilai_investasi, 
        i.jenis_investasi, 
        i.return, 
        i.tanggal_jatuh_tempo
    FROM investment i
    ': column i.tanggal_investasi does not exist
LINE 5:         i.tanggal_investasi, 
                ^
; 252)
[2025-07-07T02:05:04.188+0000] {local_task_job_runner.py:225} INFO - Task exited with return code 1
[2025-07-07T02:05:04.282+0000] {taskinstance.py:2653} INFO - 0 downstream tasks scheduled from follow-on schedule check
