[2025-07-07T06:22:03.096+0000] {taskinstance.py:1103} INFO - Dependencies all met for dep_context=non-requeueable deps ti=<TaskInstance: export_dashboard_data.export_registration_data manual__2025-07-07T06:16:59.531880+00:00 [queued]>
[2025-07-07T06:22:03.137+0000] {taskinstance.py:1103} INFO - Dependencies all met for dep_context=requeueable deps ti=<TaskInstance: export_dashboard_data.export_registration_data manual__2025-07-07T06:16:59.531880+00:00 [queued]>
[2025-07-07T06:22:03.138+0000] {taskinstance.py:1308} INFO - Starting attempt 2 of 2
[2025-07-07T06:22:03.169+0000] {taskinstance.py:1327} INFO - Executing <Task(PythonOperator): export_registration_data> on 2025-07-07 06:16:59.531880+00:00
[2025-07-07T06:22:03.179+0000] {standard_task_runner.py:57} INFO - Started process 501 to run task
[2025-07-07T06:22:03.188+0000] {standard_task_runner.py:84} INFO - Running: ['airflow', 'tasks', 'run', 'export_dashboard_data', 'export_registration_data', 'manual__2025-07-07T06:16:59.531880+00:00', '--job-id', '187', '--raw', '--subdir', 'DAGS_FOLDER/export_dashboard_data.py', '--cfg-path', '/tmp/tmpcc77rcdx']
[2025-07-07T06:22:03.191+0000] {standard_task_runner.py:85} INFO - Job 187: Subtask export_registration_data
[2025-07-07T06:22:03.351+0000] {task_command.py:410} INFO - Running <TaskInstance: export_dashboard_data.export_registration_data manual__2025-07-07T06:16:59.531880+00:00 [running]> on host 1622b3ff66d0
[2025-07-07T06:22:03.514+0000] {taskinstance.py:1547} INFO - Exporting env vars: AIRFLOW_CTX_DAG_OWNER='airflow' AIRFLOW_CTX_DAG_ID='export_dashboard_data' AIRFLOW_CTX_TASK_ID='export_registration_data' AIRFLOW_CTX_EXECUTION_DATE='2025-07-07T06:16:59.531880+00:00' AIRFLOW_CTX_TRY_NUMBER='2' AIRFLOW_CTX_DAG_RUN_ID='manual__2025-07-07T06:16:59.531880+00:00'
[2025-07-07T06:22:03.545+0000] {base.py:73} INFO - Using connection ID '***_insurance_dw' for task execution.
[2025-07-07T06:22:03.617+0000] {taskinstance.py:1824} ERROR - Task failed with exception
Traceback (most recent call last):
  File "/home/airflow/.local/lib/python3.7/site-packages/airflow/operators/python.py", line 181, in execute
    return_value = self.execute_callable()
  File "/home/airflow/.local/lib/python3.7/site-packages/airflow/operators/python.py", line 198, in execute_callable
    return self.python_callable(*self.op_args, **self.op_kwargs)
  File "/opt/airflow/dags/export_dashboard_data.py", line 62, in export_registration_dashboard_data
    df.to_csv(output_path, index=False)
  File "/home/airflow/.local/lib/python3.7/site-packages/pandas/core/generic.py", line 3482, in to_csv
    storage_options=storage_options,
  File "/home/airflow/.local/lib/python3.7/site-packages/pandas/io/formats/format.py", line 1105, in to_csv
    csv_formatter.save()
  File "/home/airflow/.local/lib/python3.7/site-packages/pandas/io/formats/csvs.py", line 243, in save
    storage_options=self.storage_options,
  File "/home/airflow/.local/lib/python3.7/site-packages/pandas/io/common.py", line 707, in get_handle
    newline="",
PermissionError: [Errno 13] Permission denied: '/opt/airflow/data/dashboard/registration_metrics_20250707.csv'
[2025-07-07T06:22:03.643+0000] {taskinstance.py:1350} INFO - Marking task as FAILED. dag_id=export_dashboard_data, task_id=export_registration_data, execution_date=20250707T061659, start_date=20250707T062203, end_date=20250707T062203
[2025-07-07T06:22:03.682+0000] {standard_task_runner.py:109} ERROR - Failed to execute job 187 for task export_registration_data ([Errno 13] Permission denied: '/opt/airflow/data/dashboard/registration_metrics_20250707.csv'; 501)
[2025-07-07T06:22:03.692+0000] {local_task_job_runner.py:225} INFO - Task exited with return code 1
[2025-07-07T06:22:03.756+0000] {taskinstance.py:2653} INFO - 0 downstream tasks scheduled from follow-on schedule check
