[2025-07-07T01:47:12.011+0000] {taskinstance.py:1103} INFO - Dependencies all met for dep_context=non-requeueable deps ti=<TaskInstance: etl_dim_employee.run_etl_dim_employee scheduled__2025-07-05T01:00:00+00:00 [queued]>
[2025-07-07T01:47:12.056+0000] {taskinstance.py:1103} INFO - Dependencies all met for dep_context=requeueable deps ti=<TaskInstance: etl_dim_employee.run_etl_dim_employee scheduled__2025-07-05T01:00:00+00:00 [queued]>
[2025-07-07T01:47:12.057+0000] {taskinstance.py:1308} INFO - Starting attempt 2 of 2
[2025-07-07T01:47:12.104+0000] {taskinstance.py:1327} INFO - Executing <Task(PythonOperator): run_etl_dim_employee> on 2025-07-05 01:00:00+00:00
[2025-07-07T01:47:12.116+0000] {standard_task_runner.py:57} INFO - Started process 103 to run task
[2025-07-07T01:47:12.121+0000] {standard_task_runner.py:84} INFO - Running: ['airflow', 'tasks', 'run', 'etl_dim_employee', 'run_etl_dim_employee', 'scheduled__2025-07-05T01:00:00+00:00', '--job-id', '42', '--raw', '--subdir', 'DAGS_FOLDER/etl_dim_employee.py', '--cfg-path', '/tmp/tmp77lwf2_3']
[2025-07-07T01:47:12.130+0000] {standard_task_runner.py:85} INFO - Job 42: Subtask run_etl_dim_employee
[2025-07-07T01:47:12.423+0000] {task_command.py:410} INFO - Running <TaskInstance: etl_dim_employee.run_etl_dim_employee scheduled__2025-07-05T01:00:00+00:00 [running]> on host 1622b3ff66d0
[2025-07-07T01:47:12.796+0000] {taskinstance.py:1547} INFO - Exporting env vars: AIRFLOW_CTX_DAG_OWNER='airflow' AIRFLOW_CTX_DAG_ID='etl_dim_employee' AIRFLOW_CTX_TASK_ID='run_etl_dim_employee' AIRFLOW_CTX_EXECUTION_DATE='2025-07-05T01:00:00+00:00' AIRFLOW_CTX_TRY_NUMBER='2' AIRFLOW_CTX_DAG_RUN_ID='scheduled__2025-07-05T01:00:00+00:00'
[2025-07-07T01:47:13.157+0000] {taskinstance.py:1824} ERROR - Task failed with exception
Traceback (most recent call last):
  File "/home/airflow/.local/lib/python3.7/site-packages/airflow/operators/python.py", line 181, in execute
    return_value = self.execute_callable()
  File "/home/airflow/.local/lib/python3.7/site-packages/airflow/operators/python.py", line 198, in execute_callable
    return self.python_callable(*self.op_args, **self.op_kwargs)
  File "/opt/airflow/dags/etl_dim_employee.py", line 120, in etl_dim_employee
    df = extract_employee_data()
  File "/opt/airflow/dags/etl_dim_employee.py", line 40, in extract_employee_data
    df = source_hook.get_pandas_df(sql)
  File "/home/airflow/.local/lib/python3.7/site-packages/airflow/providers/common/sql/hooks/sql.py", line 200, in get_pandas_df
    with closing(self.get_conn()) as conn:
  File "/home/airflow/.local/lib/python3.7/site-packages/airflow/providers/postgres/hooks/postgres.py", line 118, in get_conn
    conn = deepcopy(self.connection or self.get_connection(conn_id))
  File "/home/airflow/.local/lib/python3.7/site-packages/airflow/hooks/base.py", line 72, in get_connection
    conn = Connection.get_connection_from_secrets(conn_id)
  File "/home/airflow/.local/lib/python3.7/site-packages/airflow/models/connection.py", line 463, in get_connection_from_secrets
    raise AirflowNotFoundException(f"The conn_id `{conn_id}` isn't defined")
airflow.exceptions.AirflowNotFoundException: The conn_id `***_insurance_bi` isn't defined
[2025-07-07T01:47:13.170+0000] {taskinstance.py:1350} INFO - Marking task as FAILED. dag_id=etl_dim_employee, task_id=run_etl_dim_employee, execution_date=20250705T010000, start_date=20250707T014712, end_date=20250707T014713
[2025-07-07T01:47:13.247+0000] {standard_task_runner.py:109} ERROR - Failed to execute job 42 for task run_etl_dim_employee (The conn_id `***_insurance_bi` isn't defined; 103)
[2025-07-07T01:47:13.283+0000] {local_task_job_runner.py:225} INFO - Task exited with return code 1
[2025-07-07T01:47:13.504+0000] {taskinstance.py:2653} INFO - 0 downstream tasks scheduled from follow-on schedule check
