[2025-07-07T01:47:11.691+0000] {taskinstance.py:1103} INFO - Dependencies all met for dep_context=non-requeueable deps ti=<TaskInstance: export_dashboard_data.export_customer_service_data scheduled__2025-07-05T02:00:00+00:00 [queued]>
[2025-07-07T01:47:11.716+0000] {taskinstance.py:1103} INFO - Dependencies all met for dep_context=requeueable deps ti=<TaskInstance: export_dashboard_data.export_customer_service_data scheduled__2025-07-05T02:00:00+00:00 [queued]>
[2025-07-07T01:47:11.717+0000] {taskinstance.py:1308} INFO - Starting attempt 2 of 2
[2025-07-07T01:47:11.742+0000] {taskinstance.py:1327} INFO - Executing <Task(PythonOperator): export_customer_service_data> on 2025-07-05 02:00:00+00:00
[2025-07-07T01:47:11.754+0000] {standard_task_runner.py:57} INFO - Started process 91 to run task
[2025-07-07T01:47:11.760+0000] {standard_task_runner.py:84} INFO - Running: ['airflow', 'tasks', 'run', 'export_dashboard_data', 'export_customer_service_data', 'scheduled__2025-07-05T02:00:00+00:00', '--job-id', '32', '--raw', '--subdir', 'DAGS_FOLDER/export_dashboard_data.py', '--cfg-path', '/tmp/tmpr56l7gk5']
[2025-07-07T01:47:11.764+0000] {standard_task_runner.py:85} INFO - Job 32: Subtask export_customer_service_data
[2025-07-07T01:47:12.203+0000] {task_command.py:410} INFO - Running <TaskInstance: export_dashboard_data.export_customer_service_data scheduled__2025-07-05T02:00:00+00:00 [running]> on host 1622b3ff66d0
[2025-07-07T01:47:12.609+0000] {taskinstance.py:1547} INFO - Exporting env vars: AIRFLOW_CTX_DAG_OWNER='airflow' AIRFLOW_CTX_DAG_ID='export_dashboard_data' AIRFLOW_CTX_TASK_ID='export_customer_service_data' AIRFLOW_CTX_EXECUTION_DATE='2025-07-05T02:00:00+00:00' AIRFLOW_CTX_TRY_NUMBER='2' AIRFLOW_CTX_DAG_RUN_ID='scheduled__2025-07-05T02:00:00+00:00'
[2025-07-07T01:47:12.726+0000] {taskinstance.py:1824} ERROR - Task failed with exception
Traceback (most recent call last):
  File "/home/airflow/.local/lib/python3.7/site-packages/airflow/operators/python.py", line 181, in execute
    return_value = self.execute_callable()
  File "/home/airflow/.local/lib/python3.7/site-packages/airflow/operators/python.py", line 198, in execute_callable
    return self.python_callable(*self.op_args, **self.op_kwargs)
  File "/opt/airflow/dags/export_dashboard_data.py", line 217, in export_customer_service_dashboard_data
    df = dw_hook.get_pandas_df(sql)
  File "/home/airflow/.local/lib/python3.7/site-packages/airflow/providers/common/sql/hooks/sql.py", line 200, in get_pandas_df
    with closing(self.get_conn()) as conn:
  File "/home/airflow/.local/lib/python3.7/site-packages/airflow/providers/postgres/hooks/postgres.py", line 118, in get_conn
    conn = deepcopy(self.connection or self.get_connection(conn_id))
  File "/home/airflow/.local/lib/python3.7/site-packages/airflow/hooks/base.py", line 72, in get_connection
    conn = Connection.get_connection_from_secrets(conn_id)
  File "/home/airflow/.local/lib/python3.7/site-packages/airflow/models/connection.py", line 463, in get_connection_from_secrets
    raise AirflowNotFoundException(f"The conn_id `{conn_id}` isn't defined")
airflow.exceptions.AirflowNotFoundException: The conn_id `***_insurance_dw` isn't defined
[2025-07-07T01:47:12.740+0000] {taskinstance.py:1350} INFO - Marking task as FAILED. dag_id=export_dashboard_data, task_id=export_customer_service_data, execution_date=20250705T020000, start_date=20250707T014711, end_date=20250707T014712
[2025-07-07T01:47:12.779+0000] {standard_task_runner.py:109} ERROR - Failed to execute job 32 for task export_customer_service_data (The conn_id `***_insurance_dw` isn't defined; 91)
[2025-07-07T01:47:12.803+0000] {local_task_job_runner.py:225} INFO - Task exited with return code 1
[2025-07-07T01:47:13.497+0000] {taskinstance.py:2653} INFO - 0 downstream tasks scheduled from follow-on schedule check
