[2025-07-07T06:17:01.660+0000] {taskinstance.py:1103} INFO - Dependencies all met for dep_context=non-requeueable deps ti=<TaskInstance: export_dashboard_data.export_claims_data manual__2025-07-07T06:16:59.531880+00:00 [queued]>
[2025-07-07T06:17:01.684+0000] {taskinstance.py:1103} INFO - Dependencies all met for dep_context=requeueable deps ti=<TaskInstance: export_dashboard_data.export_claims_data manual__2025-07-07T06:16:59.531880+00:00 [queued]>
[2025-07-07T06:17:01.684+0000] {taskinstance.py:1308} INFO - Starting attempt 1 of 2
[2025-07-07T06:17:01.710+0000] {taskinstance.py:1327} INFO - Executing <Task(PythonOperator): export_claims_data> on 2025-07-07 06:16:59.531880+00:00
[2025-07-07T06:17:01.718+0000] {standard_task_runner.py:57} INFO - Started process 487 to run task
[2025-07-07T06:17:01.723+0000] {standard_task_runner.py:84} INFO - Running: ['airflow', 'tasks', 'run', 'export_dashboard_data', 'export_claims_data', 'manual__2025-07-07T06:16:59.531880+00:00', '--job-id', '183', '--raw', '--subdir', 'DAGS_FOLDER/export_dashboard_data.py', '--cfg-path', '/tmp/tmpabphj5il']
[2025-07-07T06:17:01.726+0000] {standard_task_runner.py:85} INFO - Job 183: Subtask export_claims_data
[2025-07-07T06:17:01.803+0000] {task_command.py:410} INFO - Running <TaskInstance: export_dashboard_data.export_claims_data manual__2025-07-07T06:16:59.531880+00:00 [running]> on host 1622b3ff66d0
[2025-07-07T06:17:01.925+0000] {taskinstance.py:1547} INFO - Exporting env vars: AIRFLOW_CTX_DAG_OWNER='airflow' AIRFLOW_CTX_DAG_ID='export_dashboard_data' AIRFLOW_CTX_TASK_ID='export_claims_data' AIRFLOW_CTX_EXECUTION_DATE='2025-07-07T06:16:59.531880+00:00' AIRFLOW_CTX_TRY_NUMBER='1' AIRFLOW_CTX_DAG_RUN_ID='manual__2025-07-07T06:16:59.531880+00:00'
[2025-07-07T06:17:01.944+0000] {base.py:73} INFO - Using connection ID '***_insurance_dw' for task execution.
[2025-07-07T06:17:01.954+0000] {taskinstance.py:1824} ERROR - Task failed with exception
Traceback (most recent call last):
  File "/home/airflow/.local/lib/python3.7/site-packages/pandas/io/sql.py", line 2056, in execute
    cur.execute(*args, **kwargs)
psycopg2.errors.UndefinedColumn: column dp.nama_product does not exist
LINE 6:         dp.nama_product,
                ^
HINT:  Perhaps you meant to reference the column "dpr.nama_product".


The above exception was the direct cause of the following exception:

Traceback (most recent call last):
  File "/home/airflow/.local/lib/python3.7/site-packages/airflow/operators/python.py", line 181, in execute
    return_value = self.execute_callable()
  File "/home/airflow/.local/lib/python3.7/site-packages/airflow/operators/python.py", line 198, in execute_callable
    return self.python_callable(*self.op_args, **self.op_kwargs)
  File "/opt/airflow/dags/export_dashboard_data.py", line 179, in export_claims_dashboard_data
    df = dw_hook.get_pandas_df(sql)
  File "/home/airflow/.local/lib/python3.7/site-packages/airflow/providers/common/sql/hooks/sql.py", line 201, in get_pandas_df
    return psql.read_sql(sql, con=conn, params=parameters, **kwargs)
  File "/home/airflow/.local/lib/python3.7/site-packages/pandas/io/sql.py", line 608, in read_sql
    chunksize=chunksize,
  File "/home/airflow/.local/lib/python3.7/site-packages/pandas/io/sql.py", line 2116, in read_query
    cursor = self.execute(*args)
  File "/home/airflow/.local/lib/python3.7/site-packages/pandas/io/sql.py", line 2068, in execute
    raise ex from exc
pandas.io.sql.DatabaseError: Execution failed on sql '
    SELECT 
        dt.year_actual,
        dt.month_name,
        fc.claim_type,
        dp.nama_product,
        dp.jenis_product,
        COUNT(fc.claim_id) as total_claims,
        SUM(fc.claim_amount) as total_claim_amount,
        SUM(fc.approved_amount) as total_approved_amount,
        AVG(fc.processing_days) as avg_processing_days,
        SUM(CASE WHEN fc.rejection_flag THEN 1 ELSE 0 END) as rejected_claims,
        SUM(CASE WHEN fc.rejection_flag THEN 1 ELSE 0 END)::float / 
            NULLIF(COUNT(fc.claim_id), 0) * 100 as rejection_rate
    FROM fact_claim fc
    JOIN dim_policy dp ON fc.policy_key = dp.policy_key
    JOIN dim_product dpr ON dp.product_key = dpr.product_key
    JOIN dim_time dt ON fc.time_key_submitted = dt.time_key
    WHERE dt.date_actual >= CURRENT_DATE - INTERVAL '12 months'
      AND dp.is_current = TRUE
      AND dpr.is_current = TRUE
    GROUP BY dt.year_actual, dt.month_name, fc.claim_type, dp.nama_product, dp.jenis_product
    ORDER BY dt.year_actual, dt.month_name
    ': column dp.nama_product does not exist
LINE 6:         dp.nama_product,
                ^
HINT:  Perhaps you meant to reference the column "dpr.nama_product".

[2025-07-07T06:17:02.325+0000] {taskinstance.py:1350} INFO - Marking task as UP_FOR_RETRY. dag_id=export_dashboard_data, task_id=export_claims_data, execution_date=20250707T061659, start_date=20250707T061701, end_date=20250707T061702
[2025-07-07T06:17:02.334+0000] {standard_task_runner.py:109} ERROR - Failed to execute job 183 for task export_claims_data (Execution failed on sql '
    SELECT 
        dt.year_actual,
        dt.month_name,
        fc.claim_type,
        dp.nama_product,
        dp.jenis_product,
        COUNT(fc.claim_id) as total_claims,
        SUM(fc.claim_amount) as total_claim_amount,
        SUM(fc.approved_amount) as total_approved_amount,
        AVG(fc.processing_days) as avg_processing_days,
        SUM(CASE WHEN fc.rejection_flag THEN 1 ELSE 0 END) as rejected_claims,
        SUM(CASE WHEN fc.rejection_flag THEN 1 ELSE 0 END)::float / 
            NULLIF(COUNT(fc.claim_id), 0) * 100 as rejection_rate
    FROM fact_claim fc
    JOIN dim_policy dp ON fc.policy_key = dp.policy_key
    JOIN dim_product dpr ON dp.product_key = dpr.product_key
    JOIN dim_time dt ON fc.time_key_submitted = dt.time_key
    WHERE dt.date_actual >= CURRENT_DATE - INTERVAL '12 months'
      AND dp.is_current = TRUE
      AND dpr.is_current = TRUE
    GROUP BY dt.year_actual, dt.month_name, fc.claim_type, dp.nama_product, dp.jenis_product
    ORDER BY dt.year_actual, dt.month_name
    ': column dp.nama_product does not exist
LINE 6:         dp.nama_product,
                ^
HINT:  Perhaps you meant to reference the column "dpr.nama_product".
; 487)
[2025-07-07T06:17:02.357+0000] {local_task_job_runner.py:225} INFO - Task exited with return code 1
[2025-07-07T06:17:02.391+0000] {taskinstance.py:2653} INFO - 0 downstream tasks scheduled from follow-on schedule check
