[2025-07-07T01:47:11.701+0000] {taskinstance.py:1103} INFO - Dependencies all met for dep_context=non-requeueable deps ti=<TaskInstance: etl_fact_registration.run_etl_fact_registration scheduled__2025-07-05T02:00:00+00:00 [queued]>
[2025-07-07T01:47:11.722+0000] {taskinstance.py:1103} INFO - Dependencies all met for dep_context=requeueable deps ti=<TaskInstance: etl_fact_registration.run_etl_fact_registration scheduled__2025-07-05T02:00:00+00:00 [queued]>
[2025-07-07T01:47:11.723+0000] {taskinstance.py:1308} INFO - Starting attempt 2 of 2
[2025-07-07T01:47:11.781+0000] {taskinstance.py:1327} INFO - Executing <Task(PythonOperator): run_etl_fact_registration> on 2025-07-05 02:00:00+00:00
[2025-07-07T01:47:11.802+0000] {standard_task_runner.py:57} INFO - Started process 93 to run task
[2025-07-07T01:47:11.837+0000] {standard_task_runner.py:84} INFO - Running: ['airflow', 'tasks', 'run', 'etl_fact_registration', 'run_etl_fact_registration', 'scheduled__2025-07-05T02:00:00+00:00', '--job-id', '35', '--raw', '--subdir', 'DAGS_FOLDER/etl_fact_registration.py', '--cfg-path', '/tmp/tmpb7miqd_s']
[2025-07-07T01:47:11.858+0000] {standard_task_runner.py:85} INFO - Job 35: Subtask run_etl_fact_registration
[2025-07-07T01:47:12.226+0000] {task_command.py:410} INFO - Running <TaskInstance: etl_fact_registration.run_etl_fact_registration scheduled__2025-07-05T02:00:00+00:00 [running]> on host 1622b3ff66d0
[2025-07-07T01:47:12.655+0000] {taskinstance.py:1547} INFO - Exporting env vars: AIRFLOW_CTX_DAG_OWNER='airflow' AIRFLOW_CTX_DAG_ID='etl_fact_registration' AIRFLOW_CTX_TASK_ID='run_etl_fact_registration' AIRFLOW_CTX_EXECUTION_DATE='2025-07-05T02:00:00+00:00' AIRFLOW_CTX_TRY_NUMBER='2' AIRFLOW_CTX_DAG_RUN_ID='scheduled__2025-07-05T02:00:00+00:00'
[2025-07-07T01:47:12.752+0000] {taskinstance.py:1824} ERROR - Task failed with exception
Traceback (most recent call last):
  File "/home/airflow/.local/lib/python3.7/site-packages/airflow/operators/python.py", line 181, in execute
    return_value = self.execute_callable()
  File "/home/airflow/.local/lib/python3.7/site-packages/airflow/operators/python.py", line 198, in execute_callable
    return self.python_callable(*self.op_args, **self.op_kwargs)
  File "/opt/airflow/dags/etl_fact_registration.py", line 148, in etl_fact_registration
    df = extract_policy_data()
  File "/opt/airflow/dags/etl_fact_registration.py", line 45, in extract_policy_data
    df = source_hook.get_pandas_df(sql)
  File "/home/airflow/.local/lib/python3.7/site-packages/airflow/providers/common/sql/hooks/sql.py", line 200, in get_pandas_df
    with closing(self.get_conn()) as conn:
  File "/home/airflow/.local/lib/python3.7/site-packages/airflow/providers/postgres/hooks/postgres.py", line 118, in get_conn
    conn = deepcopy(self.connection or self.get_connection(conn_id))
  File "/home/airflow/.local/lib/python3.7/site-packages/airflow/hooks/base.py", line 72, in get_connection
    conn = Connection.get_connection_from_secrets(conn_id)
  File "/home/airflow/.local/lib/python3.7/site-packages/airflow/models/connection.py", line 463, in get_connection_from_secrets
    raise AirflowNotFoundException(f"The conn_id `{conn_id}` isn't defined")
airflow.exceptions.AirflowNotFoundException: The conn_id `***_insurance_bi` isn't defined
[2025-07-07T01:47:12.763+0000] {taskinstance.py:1350} INFO - Marking task as FAILED. dag_id=etl_fact_registration, task_id=run_etl_fact_registration, execution_date=20250705T020000, start_date=20250707T014711, end_date=20250707T014712
[2025-07-07T01:47:12.857+0000] {standard_task_runner.py:109} ERROR - Failed to execute job 35 for task run_etl_fact_registration (The conn_id `***_insurance_bi` isn't defined; 93)
[2025-07-07T01:47:12.912+0000] {local_task_job_runner.py:225} INFO - Task exited with return code 1
[2025-07-07T01:47:13.493+0000] {taskinstance.py:2653} INFO - 0 downstream tasks scheduled from follow-on schedule check
