[2025-07-07T01:47:14.880+0000] {taskinstance.py:1103} INFO - Dependencies all met for dep_context=non-requeueable deps ti=<TaskInstance: export_dashboard_data.export_sales_data scheduled__2025-07-05T02:00:00+00:00 [queued]>
[2025-07-07T01:47:14.898+0000] {taskinstance.py:1103} INFO - Dependencies all met for dep_context=requeueable deps ti=<TaskInstance: export_dashboard_data.export_sales_data scheduled__2025-07-05T02:00:00+00:00 [queued]>
[2025-07-07T01:47:14.899+0000] {taskinstance.py:1308} INFO - Starting attempt 2 of 2
[2025-07-07T01:47:14.917+0000] {taskinstance.py:1327} INFO - Executing <Task(PythonOperator): export_sales_data> on 2025-07-05 02:00:00+00:00
[2025-07-07T01:47:14.924+0000] {standard_task_runner.py:57} INFO - Started process 121 to run task
[2025-07-07T01:47:14.928+0000] {standard_task_runner.py:84} INFO - Running: ['airflow', 'tasks', 'run', 'export_dashboard_data', 'export_sales_data', 'scheduled__2025-07-05T02:00:00+00:00', '--job-id', '46', '--raw', '--subdir', 'DAGS_FOLDER/export_dashboard_data.py', '--cfg-path', '/tmp/tmphct9eu0e']
[2025-07-07T01:47:14.930+0000] {standard_task_runner.py:85} INFO - Job 46: Subtask export_sales_data
[2025-07-07T01:47:15.092+0000] {task_command.py:410} INFO - Running <TaskInstance: export_dashboard_data.export_sales_data scheduled__2025-07-05T02:00:00+00:00 [running]> on host 1622b3ff66d0
[2025-07-07T01:47:15.414+0000] {taskinstance.py:1547} INFO - Exporting env vars: AIRFLOW_CTX_DAG_OWNER='airflow' AIRFLOW_CTX_DAG_ID='export_dashboard_data' AIRFLOW_CTX_TASK_ID='export_sales_data' AIRFLOW_CTX_EXECUTION_DATE='2025-07-05T02:00:00+00:00' AIRFLOW_CTX_TRY_NUMBER='2' AIRFLOW_CTX_DAG_RUN_ID='scheduled__2025-07-05T02:00:00+00:00'
[2025-07-07T01:47:15.495+0000] {taskinstance.py:1824} ERROR - Task failed with exception
Traceback (most recent call last):
  File "/home/airflow/.local/lib/python3.7/site-packages/airflow/operators/python.py", line 181, in execute
    return_value = self.execute_callable()
  File "/home/airflow/.local/lib/python3.7/site-packages/airflow/operators/python.py", line 198, in execute_callable
    return self.python_callable(*self.op_args, **self.op_kwargs)
  File "/opt/airflow/dags/export_dashboard_data.py", line 135, in export_sales_dashboard_data
    df = dw_hook.get_pandas_df(sql)
  File "/home/airflow/.local/lib/python3.7/site-packages/airflow/providers/common/sql/hooks/sql.py", line 200, in get_pandas_df
    with closing(self.get_conn()) as conn:
  File "/home/airflow/.local/lib/python3.7/site-packages/airflow/providers/postgres/hooks/postgres.py", line 118, in get_conn
    conn = deepcopy(self.connection or self.get_connection(conn_id))
  File "/home/airflow/.local/lib/python3.7/site-packages/airflow/hooks/base.py", line 72, in get_connection
    conn = Connection.get_connection_from_secrets(conn_id)
  File "/home/airflow/.local/lib/python3.7/site-packages/airflow/models/connection.py", line 463, in get_connection_from_secrets
    raise AirflowNotFoundException(f"The conn_id `{conn_id}` isn't defined")
airflow.exceptions.AirflowNotFoundException: The conn_id `***_insurance_dw` isn't defined
[2025-07-07T01:47:15.509+0000] {taskinstance.py:1350} INFO - Marking task as FAILED. dag_id=export_dashboard_data, task_id=export_sales_data, execution_date=20250705T020000, start_date=20250707T014714, end_date=20250707T014715
[2025-07-07T01:47:15.572+0000] {standard_task_runner.py:109} ERROR - Failed to execute job 46 for task export_sales_data (The conn_id `***_insurance_dw` isn't defined; 121)
[2025-07-07T01:47:15.602+0000] {local_task_job_runner.py:225} INFO - Task exited with return code 1
[2025-07-07T01:47:15.716+0000] {taskinstance.py:2653} INFO - 0 downstream tasks scheduled from follow-on schedule check
