[2025-07-07T02:00:01.357+0000] {taskinstance.py:1103} INFO - Dependencies all met for dep_context=non-requeueable deps ti=<TaskInstance: etl_fact_sales_activity.run_etl_fact_sales_activity scheduled__2025-07-06T02:00:00+00:00 [queued]>
[2025-07-07T02:00:01.407+0000] {taskinstance.py:1103} INFO - Dependencies all met for dep_context=requeueable deps ti=<TaskInstance: etl_fact_sales_activity.run_etl_fact_sales_activity scheduled__2025-07-06T02:00:00+00:00 [queued]>
[2025-07-07T02:00:01.410+0000] {taskinstance.py:1308} INFO - Starting attempt 1 of 2
[2025-07-07T02:00:01.477+0000] {taskinstance.py:1327} INFO - Executing <Task(PythonOperator): run_etl_fact_sales_activity> on 2025-07-06 02:00:00+00:00
[2025-07-07T02:00:01.492+0000] {standard_task_runner.py:57} INFO - Started process 185 to run task
[2025-07-07T02:00:01.500+0000] {standard_task_runner.py:84} INFO - Running: ['airflow', 'tasks', 'run', 'etl_fact_sales_activity', 'run_etl_fact_sales_activity', 'scheduled__2025-07-06T02:00:00+00:00', '--job-id', '68', '--raw', '--subdir', 'DAGS_FOLDER/etl_fact_sales_activity.py', '--cfg-path', '/tmp/tmp4zbdy4tm']
[2025-07-07T02:00:01.504+0000] {standard_task_runner.py:85} INFO - Job 68: Subtask run_etl_fact_sales_activity
[2025-07-07T02:00:01.859+0000] {task_command.py:410} INFO - Running <TaskInstance: etl_fact_sales_activity.run_etl_fact_sales_activity scheduled__2025-07-06T02:00:00+00:00 [running]> on host 1622b3ff66d0
[2025-07-07T02:00:02.090+0000] {taskinstance.py:1547} INFO - Exporting env vars: AIRFLOW_CTX_DAG_OWNER='airflow' AIRFLOW_CTX_DAG_ID='etl_fact_sales_activity' AIRFLOW_CTX_TASK_ID='run_etl_fact_sales_activity' AIRFLOW_CTX_EXECUTION_DATE='2025-07-06T02:00:00+00:00' AIRFLOW_CTX_TRY_NUMBER='1' AIRFLOW_CTX_DAG_RUN_ID='scheduled__2025-07-06T02:00:00+00:00'
[2025-07-07T02:00:02.182+0000] {base.py:73} INFO - Using connection ID '***_insurance_bi' for task execution.
[2025-07-07T02:00:02.319+0000] {taskinstance.py:1824} ERROR - Task failed with exception
Traceback (most recent call last):
  File "/home/airflow/.local/lib/python3.7/site-packages/airflow/operators/python.py", line 181, in execute
    return_value = self.execute_callable()
  File "/home/airflow/.local/lib/python3.7/site-packages/airflow/operators/python.py", line 198, in execute_callable
    return self.python_callable(*self.op_args, **self.op_kwargs)
  File "/opt/airflow/dags/etl_fact_sales_activity.py", line 109, in etl_fact_sales_activity
    transformed_df = transform_sales_activity(df)
  File "/opt/airflow/dags/etl_fact_sales_activity.py", line 33, in transform_sales_activity
    emp_keys = dw_hook.get_pandas_df("SELECT employee_id, employee_key FROM dim_employee WHERE is_current = TRUE")
  File "/home/airflow/.local/lib/python3.7/site-packages/airflow/providers/common/sql/hooks/sql.py", line 200, in get_pandas_df
    with closing(self.get_conn()) as conn:
  File "/home/airflow/.local/lib/python3.7/site-packages/airflow/providers/postgres/hooks/postgres.py", line 118, in get_conn
    conn = deepcopy(self.connection or self.get_connection(conn_id))
  File "/home/airflow/.local/lib/python3.7/site-packages/airflow/hooks/base.py", line 72, in get_connection
    conn = Connection.get_connection_from_secrets(conn_id)
  File "/home/airflow/.local/lib/python3.7/site-packages/airflow/models/connection.py", line 463, in get_connection_from_secrets
    raise AirflowNotFoundException(f"The conn_id `{conn_id}` isn't defined")
airflow.exceptions.AirflowNotFoundException: The conn_id `***_insurance_dw` isn't defined
[2025-07-07T02:00:02.331+0000] {taskinstance.py:1350} INFO - Marking task as UP_FOR_RETRY. dag_id=etl_fact_sales_activity, task_id=run_etl_fact_sales_activity, execution_date=20250706T020000, start_date=20250707T020001, end_date=20250707T020002
[2025-07-07T02:00:02.374+0000] {standard_task_runner.py:109} ERROR - Failed to execute job 68 for task run_etl_fact_sales_activity (The conn_id `***_insurance_dw` isn't defined; 185)
[2025-07-07T02:00:02.387+0000] {local_task_job_runner.py:225} INFO - Task exited with return code 1
[2025-07-07T02:00:02.444+0000] {taskinstance.py:2653} INFO - 0 downstream tasks scheduled from follow-on schedule check
