[2025-07-07T06:17:01.600+0000] {taskinstance.py:1103} INFO - Dependencies all met for dep_context=non-requeueable deps ti=<TaskInstance: export_dashboard_data.export_customer_service_data manual__2025-07-07T06:16:59.531880+00:00 [queued]>
[2025-07-07T06:17:01.617+0000] {taskinstance.py:1103} INFO - Dependencies all met for dep_context=requeueable deps ti=<TaskInstance: export_dashboard_data.export_customer_service_data manual__2025-07-07T06:16:59.531880+00:00 [queued]>
[2025-07-07T06:17:01.617+0000] {taskinstance.py:1308} INFO - Starting attempt 1 of 2
[2025-07-07T06:17:01.644+0000] {taskinstance.py:1327} INFO - Executing <Task(PythonOperator): export_customer_service_data> on 2025-07-07 06:16:59.531880+00:00
[2025-07-07T06:17:01.648+0000] {standard_task_runner.py:57} INFO - Started process 483 to run task
[2025-07-07T06:17:01.651+0000] {standard_task_runner.py:84} INFO - Running: ['airflow', 'tasks', 'run', 'export_dashboard_data', 'export_customer_service_data', 'manual__2025-07-07T06:16:59.531880+00:00', '--job-id', '180', '--raw', '--subdir', 'DAGS_FOLDER/export_dashboard_data.py', '--cfg-path', '/tmp/tmpnwd395fq']
[2025-07-07T06:17:01.654+0000] {standard_task_runner.py:85} INFO - Job 180: Subtask export_customer_service_data
[2025-07-07T06:17:01.756+0000] {task_command.py:410} INFO - Running <TaskInstance: export_dashboard_data.export_customer_service_data manual__2025-07-07T06:16:59.531880+00:00 [running]> on host 1622b3ff66d0
[2025-07-07T06:17:01.871+0000] {taskinstance.py:1547} INFO - Exporting env vars: AIRFLOW_CTX_DAG_OWNER='airflow' AIRFLOW_CTX_DAG_ID='export_dashboard_data' AIRFLOW_CTX_TASK_ID='export_customer_service_data' AIRFLOW_CTX_EXECUTION_DATE='2025-07-07T06:16:59.531880+00:00' AIRFLOW_CTX_TRY_NUMBER='1' AIRFLOW_CTX_DAG_RUN_ID='manual__2025-07-07T06:16:59.531880+00:00'
[2025-07-07T06:17:01.894+0000] {base.py:73} INFO - Using connection ID '***_insurance_dw' for task execution.
[2025-07-07T06:17:01.911+0000] {taskinstance.py:1824} ERROR - Task failed with exception
Traceback (most recent call last):
  File "/home/airflow/.local/lib/python3.7/site-packages/airflow/operators/python.py", line 181, in execute
    return_value = self.execute_callable()
  File "/home/airflow/.local/lib/python3.7/site-packages/airflow/operators/python.py", line 198, in execute_callable
    return self.python_callable(*self.op_args, **self.op_kwargs)
  File "/opt/airflow/dags/export_dashboard_data.py", line 221, in export_customer_service_dashboard_data
    df.to_csv(output_path, index=False)
  File "/home/airflow/.local/lib/python3.7/site-packages/pandas/core/generic.py", line 3482, in to_csv
    storage_options=storage_options,
  File "/home/airflow/.local/lib/python3.7/site-packages/pandas/io/formats/format.py", line 1105, in to_csv
    csv_formatter.save()
  File "/home/airflow/.local/lib/python3.7/site-packages/pandas/io/formats/csvs.py", line 243, in save
    storage_options=self.storage_options,
  File "/home/airflow/.local/lib/python3.7/site-packages/pandas/io/common.py", line 707, in get_handle
    newline="",
PermissionError: [Errno 13] Permission denied: '/opt/airflow/data/dashboard/customer_service_metrics_20250707.csv'
[2025-07-07T06:17:01.929+0000] {taskinstance.py:1350} INFO - Marking task as UP_FOR_RETRY. dag_id=export_dashboard_data, task_id=export_customer_service_data, execution_date=20250707T061659, start_date=20250707T061701, end_date=20250707T061701
[2025-07-07T06:17:01.958+0000] {standard_task_runner.py:109} ERROR - Failed to execute job 180 for task export_customer_service_data ([Errno 13] Permission denied: '/opt/airflow/data/dashboard/customer_service_metrics_20250707.csv'; 483)
[2025-07-07T06:17:01.997+0000] {local_task_job_runner.py:225} INFO - Task exited with return code 1
[2025-07-07T06:17:02.118+0000] {taskinstance.py:2653} INFO - 0 downstream tasks scheduled from follow-on schedule check
