[2025-07-07T10:07:28.117+0000] {taskinstance.py:1103} INFO - Dependencies all met for dep_context=non-requeueable deps ti=<TaskInstance: etl_fact_sales_activity.run_etl_fact_sales_activity manual__2025-07-07T10:07:25.226369+00:00 [queued]>
[2025-07-07T10:07:28.145+0000] {taskinstance.py:1103} INFO - Dependencies all met for dep_context=requeueable deps ti=<TaskInstance: etl_fact_sales_activity.run_etl_fact_sales_activity manual__2025-07-07T10:07:25.226369+00:00 [queued]>
[2025-07-07T10:07:28.147+0000] {taskinstance.py:1308} INFO - Starting attempt 1 of 2
[2025-07-07T10:07:28.198+0000] {taskinstance.py:1327} INFO - Executing <Task(PythonOperator): run_etl_fact_sales_activity> on 2025-07-07 10:07:25.226369+00:00
[2025-07-07T10:07:28.210+0000] {standard_task_runner.py:57} INFO - Started process 851 to run task
[2025-07-07T10:07:28.223+0000] {standard_task_runner.py:84} INFO - Running: ['airflow', 'tasks', 'run', 'etl_fact_sales_activity', 'run_etl_fact_sales_activity', 'manual__2025-07-07T10:07:25.226369+00:00', '--job-id', '322', '--raw', '--subdir', 'DAGS_FOLDER/etl_fact_sales_activity.py', '--cfg-path', '/tmp/tmp2zh4svn3']
[2025-07-07T10:07:28.229+0000] {standard_task_runner.py:85} INFO - Job 322: Subtask run_etl_fact_sales_activity
[2025-07-07T10:07:28.391+0000] {task_command.py:410} INFO - Running <TaskInstance: etl_fact_sales_activity.run_etl_fact_sales_activity manual__2025-07-07T10:07:25.226369+00:00 [running]> on host 1622b3ff66d0
[2025-07-07T10:07:28.766+0000] {taskinstance.py:1547} INFO - Exporting env vars: AIRFLOW_CTX_DAG_OWNER='airflow' AIRFLOW_CTX_DAG_ID='etl_fact_sales_activity' AIRFLOW_CTX_TASK_ID='run_etl_fact_sales_activity' AIRFLOW_CTX_EXECUTION_DATE='2025-07-07T10:07:25.226369+00:00' AIRFLOW_CTX_TRY_NUMBER='1' AIRFLOW_CTX_DAG_RUN_ID='manual__2025-07-07T10:07:25.226369+00:00'
[2025-07-07T10:07:28.827+0000] {base.py:73} INFO - Using connection ID '***_insurance_bi' for task execution.
[2025-07-07T10:07:34.538+0000] {base.py:73} INFO - Using connection ID '***_insurance_dw' for task execution.
[2025-07-07T10:07:35.039+0000] {base.py:73} INFO - Using connection ID '***_insurance_dw' for task execution.
[2025-07-07T10:07:40.082+0000] {base.py:73} INFO - Using connection ID '***_insurance_dw' for task execution.
[2025-07-07T10:07:40.343+0000] {base.py:73} INFO - Using connection ID '***_insurance_dw' for task execution.
[2025-07-07T10:07:40.789+0000] {base.py:73} INFO - Using connection ID '***_insurance_dw' for task execution.
[2025-07-07T10:07:42.373+0000] {taskinstance.py:1824} ERROR - Task failed with exception
Traceback (most recent call last):
  File "/home/airflow/.local/lib/python3.7/site-packages/airflow/operators/python.py", line 181, in execute
    return_value = self.execute_callable()
  File "/home/airflow/.local/lib/python3.7/site-packages/airflow/operators/python.py", line 198, in execute_callable
    return self.python_callable(*self.op_args, **self.op_kwargs)
  File "/opt/airflow/dags/etl_fact_sales_activity.py", line 109, in etl_fact_sales_activity
    transformed_df = transform_sales_activity(df)
  File "/opt/airflow/dags/etl_fact_sales_activity.py", line 45, in transform_sales_activity
    df = pd.merge(df, cust_keys, on='customer_id', how='left')
  File "/home/airflow/.local/lib/python3.7/site-packages/pandas/core/reshape/merge.py", line 119, in merge
    validate=validate,
  File "/home/airflow/.local/lib/python3.7/site-packages/pandas/core/reshape/merge.py", line 703, in __init__
    self._maybe_coerce_merge_keys()
  File "/home/airflow/.local/lib/python3.7/site-packages/pandas/core/reshape/merge.py", line 1256, in _maybe_coerce_merge_keys
    raise ValueError(msg)
ValueError: You are trying to merge on int64 and object columns. If you wish to proceed you should use pd.concat
[2025-07-07T10:07:42.531+0000] {taskinstance.py:1350} INFO - Marking task as UP_FOR_RETRY. dag_id=etl_fact_sales_activity, task_id=run_etl_fact_sales_activity, execution_date=20250707T100725, start_date=20250707T100728, end_date=20250707T100742
[2025-07-07T10:07:42.676+0000] {standard_task_runner.py:109} ERROR - Failed to execute job 322 for task run_etl_fact_sales_activity (You are trying to merge on int64 and object columns. If you wish to proceed you should use pd.concat; 851)
[2025-07-07T10:07:42.820+0000] {local_task_job_runner.py:225} INFO - Task exited with return code 1
[2025-07-07T10:07:43.068+0000] {taskinstance.py:2653} INFO - 0 downstream tasks scheduled from follow-on schedule check
