[2025-07-07T10:05:45.057+0000] {taskinstance.py:1103} INFO - Dependencies all met for dep_context=non-requeueable deps ti=<TaskInstance: etl_dim_customer.run_etl_dim_customer manual__2025-07-07T10:00:39.210710+00:00 [queued]>
[2025-07-07T10:05:45.066+0000] {taskinstance.py:1103} INFO - Dependencies all met for dep_context=requeueable deps ti=<TaskInstance: etl_dim_customer.run_etl_dim_customer manual__2025-07-07T10:00:39.210710+00:00 [queued]>
[2025-07-07T10:05:45.066+0000] {taskinstance.py:1308} INFO - Starting attempt 2 of 2
[2025-07-07T10:05:45.076+0000] {taskinstance.py:1327} INFO - Executing <Task(PythonOperator): run_etl_dim_customer> on 2025-07-07 10:00:39.210710+00:00
[2025-07-07T10:05:45.083+0000] {standard_task_runner.py:57} INFO - Started process 823 to run task
[2025-07-07T10:05:45.089+0000] {standard_task_runner.py:84} INFO - Running: ['airflow', 'tasks', 'run', 'etl_dim_customer', 'run_etl_dim_customer', 'manual__2025-07-07T10:00:39.210710+00:00', '--job-id', '312', '--raw', '--subdir', 'DAGS_FOLDER/etl_dim_customer.py', '--cfg-path', '/tmp/tmpvfenqwmp']
[2025-07-07T10:05:45.096+0000] {standard_task_runner.py:85} INFO - Job 312: Subtask run_etl_dim_customer
[2025-07-07T10:05:45.180+0000] {task_command.py:410} INFO - Running <TaskInstance: etl_dim_customer.run_etl_dim_customer manual__2025-07-07T10:00:39.210710+00:00 [running]> on host 1622b3ff66d0
[2025-07-07T10:05:45.284+0000] {taskinstance.py:1547} INFO - Exporting env vars: AIRFLOW_CTX_DAG_OWNER='airflow' AIRFLOW_CTX_DAG_ID='etl_dim_customer' AIRFLOW_CTX_TASK_ID='run_etl_dim_customer' AIRFLOW_CTX_EXECUTION_DATE='2025-07-07T10:00:39.210710+00:00' AIRFLOW_CTX_TRY_NUMBER='2' AIRFLOW_CTX_DAG_RUN_ID='manual__2025-07-07T10:00:39.210710+00:00'
[2025-07-07T10:05:45.336+0000] {base.py:73} INFO - Using connection ID '***_insurance_bi' for task execution.
[2025-07-07T10:05:47.714+0000] {base.py:73} INFO - Using connection ID '***_insurance_dw' for task execution.
[2025-07-07T10:06:24.546+0000] {taskinstance.py:1824} ERROR - Task failed with exception
Traceback (most recent call last):
  File "/home/airflow/.local/lib/python3.7/site-packages/airflow/operators/python.py", line 181, in execute
    return_value = self.execute_callable()
  File "/home/airflow/.local/lib/python3.7/site-packages/airflow/operators/python.py", line 198, in execute_callable
    return self.python_callable(*self.op_args, **self.op_kwargs)
  File "/opt/airflow/dags/etl_dim_customer.py", line 155, in etl_dim_customer
    result = load_dim_customer(df)
  File "/opt/airflow/dags/etl_dim_customer.py", line 92, in load_dim_customer
    row['alamat'], row['referral_code'], row['tanggal_daftar'])
psycopg2.errors.UndefinedFunction: operator does not exist: character varying = integer
LINE 3:                 WHERE customer_id = 71198186 AND is_current ...
                                          ^
HINT:  No operator matches the given name and argument types. You might need to add explicit type casts.

[2025-07-07T10:06:24.589+0000] {taskinstance.py:1350} INFO - Marking task as FAILED. dag_id=etl_dim_customer, task_id=run_etl_dim_customer, execution_date=20250707T100039, start_date=20250707T100545, end_date=20250707T100624
[2025-07-07T10:06:24.627+0000] {standard_task_runner.py:109} ERROR - Failed to execute job 312 for task run_etl_dim_customer (operator does not exist: character varying = integer
LINE 3:                 WHERE customer_id = 71198186 AND is_current ...
                                          ^
HINT:  No operator matches the given name and argument types. You might need to add explicit type casts.
; 823)
[2025-07-07T10:06:24.698+0000] {local_task_job_runner.py:225} INFO - Task exited with return code 1
[2025-07-07T10:06:24.751+0000] {taskinstance.py:2653} INFO - 0 downstream tasks scheduled from follow-on schedule check
