[2025-07-07T03:14:45.326+0000] {taskinstance.py:1103} INFO - Dependencies all met for dep_context=non-requeueable deps ti=<TaskInstance: etl_fact_customer_service.run_etl_fact_customer_service manual__2025-07-07T03:14:43.765194+00:00 [queued]>
[2025-07-07T03:14:45.351+0000] {taskinstance.py:1103} INFO - Dependencies all met for dep_context=requeueable deps ti=<TaskInstance: etl_fact_customer_service.run_etl_fact_customer_service manual__2025-07-07T03:14:43.765194+00:00 [queued]>
[2025-07-07T03:14:45.351+0000] {taskinstance.py:1308} INFO - Starting attempt 1 of 2
[2025-07-07T03:14:45.371+0000] {taskinstance.py:1327} INFO - Executing <Task(PythonOperator): run_etl_fact_customer_service> on 2025-07-07 03:14:43.765194+00:00
[2025-07-07T03:14:45.381+0000] {standard_task_runner.py:57} INFO - Started process 364 to run task
[2025-07-07T03:14:45.386+0000] {standard_task_runner.py:84} INFO - Running: ['airflow', 'tasks', 'run', 'etl_fact_customer_service', 'run_etl_fact_customer_service', 'manual__2025-07-07T03:14:43.765194+00:00', '--job-id', '138', '--raw', '--subdir', 'DAGS_FOLDER/etl_fact_customer_service.py', '--cfg-path', '/tmp/tmpou7u4_en']
[2025-07-07T03:14:45.391+0000] {standard_task_runner.py:85} INFO - Job 138: Subtask run_etl_fact_customer_service
[2025-07-07T03:14:45.476+0000] {task_command.py:410} INFO - Running <TaskInstance: etl_fact_customer_service.run_etl_fact_customer_service manual__2025-07-07T03:14:43.765194+00:00 [running]> on host 1622b3ff66d0
[2025-07-07T03:14:45.575+0000] {taskinstance.py:1547} INFO - Exporting env vars: AIRFLOW_CTX_DAG_OWNER='airflow' AIRFLOW_CTX_DAG_ID='etl_fact_customer_service' AIRFLOW_CTX_TASK_ID='run_etl_fact_customer_service' AIRFLOW_CTX_EXECUTION_DATE='2025-07-07T03:14:43.765194+00:00' AIRFLOW_CTX_TRY_NUMBER='1' AIRFLOW_CTX_DAG_RUN_ID='manual__2025-07-07T03:14:43.765194+00:00'
[2025-07-07T03:14:45.601+0000] {base.py:73} INFO - Using connection ID '***_insurance_bi' for task execution.
[2025-07-07T03:14:45.724+0000] {taskinstance.py:1824} ERROR - Task failed with exception
Traceback (most recent call last):
  File "/home/airflow/.local/lib/python3.7/site-packages/pandas/io/sql.py", line 2056, in execute
    cur.execute(*args, **kwargs)
psycopg2.errors.UndefinedColumn: column "resolution_date" does not exist
LINE 6:         resolution_date, satisfaction_rating, follow_up_requ...
                ^
HINT:  Perhaps you meant to reference the column "customer_service.resolution_time".


The above exception was the direct cause of the following exception:

Traceback (most recent call last):
  File "/home/airflow/.local/lib/python3.7/site-packages/airflow/operators/python.py", line 181, in execute
    return_value = self.execute_callable()
  File "/home/airflow/.local/lib/python3.7/site-packages/airflow/operators/python.py", line 198, in execute_callable
    return self.python_callable(*self.op_args, **self.op_kwargs)
  File "/opt/airflow/dags/etl_fact_customer_service.py", line 142, in etl_fact_customer_service
    df = extract_customer_service()
  File "/opt/airflow/dags/etl_fact_customer_service.py", line 27, in extract_customer_service
    df = source_hook.get_pandas_df(sql)
  File "/home/airflow/.local/lib/python3.7/site-packages/airflow/providers/common/sql/hooks/sql.py", line 201, in get_pandas_df
    return psql.read_sql(sql, con=conn, params=parameters, **kwargs)
  File "/home/airflow/.local/lib/python3.7/site-packages/pandas/io/sql.py", line 608, in read_sql
    chunksize=chunksize,
  File "/home/airflow/.local/lib/python3.7/site-packages/pandas/io/sql.py", line 2116, in read_query
    cursor = self.execute(*args)
  File "/home/airflow/.local/lib/python3.7/site-packages/pandas/io/sql.py", line 2068, in execute
    raise ex from exc
pandas.io.sql.DatabaseError: Execution failed on sql '
    SELECT 
        service_id, customer_id, employee_id, policy_id, 
        interaction_date, interaction_type, channel,
        complaint_category, duration_minutes, status,
        resolution_date, satisfaction_rating, follow_up_required
    FROM customer_service
    ': column "resolution_date" does not exist
LINE 6:         resolution_date, satisfaction_rating, follow_up_requ...
                ^
HINT:  Perhaps you meant to reference the column "customer_service.resolution_time".

[2025-07-07T03:14:45.757+0000] {taskinstance.py:1350} INFO - Marking task as UP_FOR_RETRY. dag_id=etl_fact_customer_service, task_id=run_etl_fact_customer_service, execution_date=20250707T031443, start_date=20250707T031445, end_date=20250707T031445
[2025-07-07T03:14:45.786+0000] {standard_task_runner.py:109} ERROR - Failed to execute job 138 for task run_etl_fact_customer_service (Execution failed on sql '
    SELECT 
        service_id, customer_id, employee_id, policy_id, 
        interaction_date, interaction_type, channel,
        complaint_category, duration_minutes, status,
        resolution_date, satisfaction_rating, follow_up_required
    FROM customer_service
    ': column "resolution_date" does not exist
LINE 6:         resolution_date, satisfaction_rating, follow_up_requ...
                ^
HINT:  Perhaps you meant to reference the column "customer_service.resolution_time".
; 364)
[2025-07-07T03:14:45.811+0000] {local_task_job_runner.py:225} INFO - Task exited with return code 1
[2025-07-07T03:14:45.827+0000] {taskinstance.py:2653} INFO - 0 downstream tasks scheduled from follow-on schedule check
